[
  {
    "test_case": 1,
    "error": "HTTPConnectionPool(host='localhost', port=8001): Max retries exceeded with url: /proxy/openai/generate-image (Caused by NewConnectionError('<urllib3.connection.HTTPConnection object at 0x112d19630>: Failed to establish a new connection: [Errno 61] Connection refused'))"
  },
  {
    "test_case": 2,
    "error": "HTTPConnectionPool(host='localhost', port=8001): Max retries exceeded with url: /proxy/openai/generate-image (Caused by NewConnectionError('<urllib3.connection.HTTPConnection object at 0x112d19540>: Failed to establish a new connection: [Errno 61] Connection refused'))"
  }
]