{
  "openai": [
    {
      "test_case": 1,
      "error": "HTTPConnectionPool(host='localhost', port=8001): Max retries exceeded with url: /proxy/openai/chat (Caused by NewConnectionError('<urllib3.connection.HTTPConnection object at 0x112d1b9a0>: Failed to establish a new connection: [Errno 61] Connection refused'))"
    },
    {
      "test_case": 2,
      "error": "HTTPConnectionPool(host='localhost', port=8001): Max retries exceeded with url: /proxy/openai/chat (Caused by NewConnectionError('<urllib3.connection.HTTPConnection object at 0x112d19c30>: Failed to establish a new connection: [Errno 61] Connection refused'))"
    },
    {
      "test_case": 3,
      "error": "HTTPConnectionPool(host='localhost', port=8001): Max retries exceeded with url: /proxy/openai/chat (Caused by NewConnectionError('<urllib3.connection.HTTPConnection object at 0x112d1a500>: Failed to establish a new connection: [Errno 61] Connection refused'))"
    },
    {
      "test_case": 4,
      "error": "HTTPConnectionPool(host='localhost', port=8001): Max retries exceeded with url: /proxy/openai/chat (Caused by NewConnectionError('<urllib3.connection.HTTPConnection object at 0x112d1a260>: Failed to establish a new connection: [Errno 61] Connection refused'))"
    },
    {
      "test_case": 5,
      "error": "HTTPConnectionPool(host='localhost', port=8001): Max retries exceeded with url: /proxy/openai/chat (Caused by NewConnectionError('<urllib3.connection.HTTPConnection object at 0x112d19a50>: Failed to establish a new connection: [Errno 61] Connection refused'))"
    },
    {
      "test_case": 6,
      "error": "HTTPConnectionPool(host='localhost', port=8001): Max retries exceeded with url: /proxy/openai/chat (Caused by NewConnectionError('<urllib3.connection.HTTPConnection object at 0x112d188b0>: Failed to establish a new connection: [Errno 61] Connection refused'))"
    }
  ],
  "claude": [
    {
      "test_case": 1,
      "error": "HTTPConnectionPool(host='localhost', port=8001): Max retries exceeded with url: /proxy/claude/chat (Caused by NewConnectionError('<urllib3.connection.HTTPConnection object at 0x112d18f40>: Failed to establish a new connection: [Errno 61] Connection refused'))"
    },
    {
      "test_case": 2,
      "error": "HTTPConnectionPool(host='localhost', port=8001): Max retries exceeded with url: /proxy/claude/chat (Caused by NewConnectionError('<urllib3.connection.HTTPConnection object at 0x112d19360>: Failed to establish a new connection: [Errno 61] Connection refused'))"
    },
    {
      "test_case": 3,
      "error": "HTTPConnectionPool(host='localhost', port=8001): Max retries exceeded with url: /proxy/claude/chat (Caused by NewConnectionError('<urllib3.connection.HTTPConnection object at 0x112d193c0>: Failed to establish a new connection: [Errno 61] Connection refused'))"
    },
    {
      "test_case": 4,
      "error": "HTTPConnectionPool(host='localhost', port=8001): Max retries exceeded with url: /proxy/claude/chat (Caused by NewConnectionError('<urllib3.connection.HTTPConnection object at 0x112d195a0>: Failed to establish a new connection: [Errno 61] Connection refused'))"
    },
    {
      "test_case": 5,
      "error": "HTTPConnectionPool(host='localhost', port=8001): Max retries exceeded with url: /proxy/claude/chat (Caused by NewConnectionError('<urllib3.connection.HTTPConnection object at 0x112d1b9a0>: Failed to establish a new connection: [Errno 61] Connection refused'))"
    },
    {
      "test_case": 6,
      "error": "HTTPConnectionPool(host='localhost', port=8001): Max retries exceeded with url: /proxy/claude/chat (Caused by NewConnectionError('<urllib3.connection.HTTPConnection object at 0x112d19c30>: Failed to establish a new connection: [Errno 61] Connection refused'))"
    }
  ],
  "gemini": [
    {
      "test_case": 1,
      "error": "HTTPConnectionPool(host='localhost', port=8001): Max retries exceeded with url: /proxy/gemini/chat (Caused by NewConnectionError('<urllib3.connection.HTTPConnection object at 0x112d1a710>: Failed to establish a new connection: [Errno 61] Connection refused'))"
    },
    {
      "test_case": 2,
      "error": "HTTPConnectionPool(host='localhost', port=8001): Max retries exceeded with url: /proxy/gemini/chat (Caused by NewConnectionError('<urllib3.connection.HTTPConnection object at 0x112d1af80>: Failed to establish a new connection: [Errno 61] Connection refused'))"
    },
    {
      "test_case": 3,
      "error": "HTTPConnectionPool(host='localhost', port=8001): Max retries exceeded with url: /proxy/gemini/chat (Caused by NewConnectionError('<urllib3.connection.HTTPConnection object at 0x112d19cf0>: Failed to establish a new connection: [Errno 61] Connection refused'))"
    },
    {
      "test_case": 4,
      "error": "HTTPConnectionPool(host='localhost', port=8001): Max retries exceeded with url: /proxy/gemini/chat (Caused by NewConnectionError('<urllib3.connection.HTTPConnection object at 0x112d1be50>: Failed to establish a new connection: [Errno 61] Connection refused'))"
    },
    {
      "test_case": 5,
      "error": "HTTPConnectionPool(host='localhost', port=8001): Max retries exceeded with url: /proxy/gemini/chat (Caused by NewConnectionError('<urllib3.connection.HTTPConnection object at 0x112d19000>: Failed to establish a new connection: [Errno 61] Connection refused'))"
    },
    {
      "test_case": 6,
      "error": "HTTPConnectionPool(host='localhost', port=8001): Max retries exceeded with url: /proxy/gemini/chat (Caused by NewConnectionError('<urllib3.connection.HTTPConnection object at 0x112d19300>: Failed to establish a new connection: [Errno 61] Connection refused'))"
    }
  ]
}